Workbook

Sheet Оценка
J2: Мотивация | K2: Игра - реф | L2: =C3 -> FTUE | M2: =D3 -> начало | N2: =E3 -> середина | O2: =F3 -> конец
A3: Столбец 1 | B3: Игра | C3: FTUE | D3: начало | E3: середина | F3: конец | J3: =A8 -> Выжить любой ценой | K3: =B8 -> Valheim | L3: =C8 -> Минимальная | M3: =D8 -> Средняя | N3: =E8 -> Высокая | O3: =F8 -> Высокая
A4: Выжить любой ценой | B4: Miscreated | C4: Высокая | D4: Средняя | E4: Низкая | F4: Низкая | J4: =A12 -> Хлеб насущный | K4: =B12 -> Project Zomboid | L4: =C12 -> Низкая | M4: =D12 -> Средняя | N4: =E12 -> Низкая | O4: =F12 -> Низкая
A5: Выжить любой ценой | B5: 7 Days to Die | C5: Средняя/Выс. | D5: Средняя/Выс. | E5: Средняя/Выс. | F5: Средняя/Выс. | J5: =A16 -> Дом милый дом | K5: =B16 -> Miscreated | L5: =C19 -> Максимальная | M5: =D19 -> Максимальная | N5: =E19 -> Максимальная | O5: =F19 -> Средняя
A6: Выжить любой ценой | B6: Project Zomboid | C6: Средняя | D6: Высокая | E6: Максимальная | F6: Максимальная | J6: =A22 -> Страшна, выключай! | K6: =B22 -> Miscreated | L6: =C22 -> Максимальная | M6: =D22 -> Максимальная | N6: =E22 -> Высокая | O6: =F22 -> Высокая
A7: Выжить любой ценой | B7: Space Engineers | C7: Средняя | D7: Низкая | E7: Минимальная | F7: Минимальная | J7: =A30 -> Очень нужный человек | K7: =B30 -> Project Zomboid | L7: =C30 -> Низкая | M7: =D30 -> Средняя | N7: =E30 -> Высокая | O7: =F30 -> Максимальная
A8: Выжить любой ценой | B8: Valheim | C8: Минимальная | D8: Средняя | E8: Высокая | F8: Высокая | J8: Великая цель | K8: Великая цель | L8: =C38 -> Высокая | M8: =D38 -> Средняя | N8: =E38 -> Средняя | O8: =F38 -> Высокая
A9: Выжить любой ценой | B9: The Planet Crafter | C9: Средняя/Макс | D9: Средняя/Макс | E9: Средняя/Макс | F9: Средняя/Макс | J9: =A42 -> Профессиональный рост | K9: =B42 -> Project Zomboid | L9: =C42 -> Низкая | M9: =D42 -> Средняя | N9: =E42 -> Высокая | O9: =F42 -> Средняя
A10: Хлеб насущный | B10: Miscreated | C10: Высокая | D10: Высокая | E10: Средняя | F10: Низкая | J10: =A48 -> Синдром хомяка | K10: =B48 -> Project Zomboid | L10: =C48 -> Максимальная | M10: =D48 -> Максимальная | N10: =E48 -> Максимальная | O10: =F48 -> Высокая
A11: Хлеб насущный | B11: 7 Days to Die | C11: Высокая | D11: Средняя | E11: Низкая | F11: Низкая | J11: =A56 -> Бить людей железной палкой | K11: =B56 -> Valheim | L11: =C56 -> Высокая | M11: =D56 -> Максимальная | N11: =E56 -> Максимальная | O11: =F56 -> Максимальная
A12: Хлеб насущный | B12: Project Zomboid | C12: Низкая | D12: Средняя | E12: Низкая | F12: Низкая | J12: =A59 -> Мой дом моя крепость | K12: =B59 -> 7 Days to Die | L12: =C59 -> Высокая | M12: =D59 -> Высокая | N12: =E59 -> Максимальная | O12: =F59 -> Максимальная
A13: Хлеб насущный | B13: Space Engineers | C13: Максимальная | D13: Низкая | E13: Минимальная | F13: Минимальная | J13: =A66 -> Устранение угрозы | K13: =B66 -> Project Zomboid | L13: =C66 -> Средняя | M13: =D66 -> Средняя | N13: =E66 -> Высокая | O13: =F66 -> Максимальная
A14: Хлеб насущный | B14: Valheim | C14: Минимальная | D14: Минимальная | E14: Минимальная | F14: Минимальная | J14: =A75 -> Мы свой, мы новый мир построим | K14: =B75 -> The Planet Crafter | L14: =C75 -> Минимальная | M14: =D75 -> Средняя | N14: =E75 -> Высокая | O14: =F75 -> Максимальная
A15: Хлеб насущный | B15: The Planet Crafter | C15: Средняя | D15: Низкая | E15: Минимальная | F15: Минимальная | J15: =A79 -> Шахты, заводы и склады | K15: =B79 -> Space Engineers | L15: =C79 -> Высокая | M15: =D79 -> Максимальная | N15: =E79 -> Максимальная | O15: =F79 -> Высокая
A16: Дом милый дом | B16: Miscreated | C16: Средняя | D16: Низкая | E16: Минимальная | F16: Минимальная | J16: =A84 -> Юбочка в клеточку | K16: =B84 -> Project Zomboid | L16: =C84 -> Низкая | M16: =D84 -> Средняя | N16: =E84 -> Средняя | O16: =F84 -> Высокая
A17: Дом милый дом | B17: 7 Days to Die | C17: Средняя | D17: Низкая | E17: Минимальная | F17: Минимальная | J17: =A91 -> Креативный креатив | K17: =B91 -> Space Engineers | L17: =C91 -> Минимальная | M17: =D91 -> Низкая | N17: =E91 -> Средняя | O17: =F91 -> Высокая
A18: Дом милый дом | B18: Project Zomboid | C18: Максимальная | D18: Средняя | E18: Низкая | F18: Низкая
A19: Дом милый дом | B19: Space Engineers | C19: Максимальная | D19: Максимальная | E19: Максимальная | F19: Средняя
A20: Дом милый дом | B20: Valheim | C20: Средняя | D20: Высокая | E20: Высокая | F20: Средняя
A21: Дом милый дом | B21: The Planet Crafter | C21: Высокая | D21: Высокая | E21: Средняя | F21: Средняя
A22: Страшна, выключай! | B22: Miscreated | C22: Максимальная | D22: Максимальная | E22: Высокая | F22: Высокая
A23: Страшна, выключай! | B23: 7 Days to Die | C23: Высокая | D23: Средняя | E23: Средняя | F23: Средняя
A24: Страшна, выключай! | B24: Project Zomboid | C24: Максимальная | D24: Высокая | E24: Средняя | F24: Низкая
A25: Страшна, выключай! | B25: Space Engineers | C25: Средняя | D25: Низкая | E25: Минимальная | F25: Минимальная
A26: Страшна, выключай! | B26: Valheim | C26: Низкая | D26: Минимальная | E26: Минимальная | F26: Минимальная
A27: Страшна, выключай! | B27: The Planet Crafter | C27: Низкая | D27: Минимальная | E27: Минимальная | F27: Минимальная
A28: Очень нужный человек | B28: Miscreated | C28: Минимальная | D28: Низкая | E28: Минимальная | F28: Минимальная
A29: Очень нужный человек | B29: 7 Days to Die | C29: Низкая | D29: Средняя | E29: Средняя | F29: Низкая
... A99: Исследование | B99: The Planet Crafter | C99: Средняя | D99: Высокая | E99: Максимальная | F99: Средняя

Sheet Базовые таблицы
B2: Обучение навыкам | H2: Базовые характеристики монстра по эпохам
B3: Уровень | C3: Минут на уровень | D3: Минут всего на достижение | E3: Сессий на достижение | F3: Дней на достижение | H3: Эпоха | I3: ДПС оружия персонажа | J3: Броня персонажа | K3: ХПС персонажа | L3: Оружейный навык персонажа | M3: Урон атаки персонажа | N3: Базовая броня монстра | O3: Базовые хиты монстра | P3: Базовый урон монстра
B4: 1 | C4: 5 | D4: =C4 -> 5 | E4: =D4/$C$19 -> 0.041666667 | F4: =E4/$C$20 -> 0.083333333 | H4: Примитивная | I4: =C21 -> 1 | J4: =C23 -> 1 | K4: =ROUNDUP(100/C28/60/60*C27,3) -> 0.007 | L4: 1 | M4: =I4*$C$24*L4 -> 3 | N4: =M4*$C$26 -> 1.5 | O4: =($C$25/$C$24)*(M4-N4) -> 30 | P4: =($C$22+K4*$C$25)/($C$25/$C$24)+J4*$C$24 -> 8.021
B5: 2 | C5: =C4*2 -> 10 | D5: =SUM($C$4:C5) -> 15 | E5: =D5/$C$19 -> 0.125 | F5: =E5/$C$20 -> 0.25 | H5: Железа | I5: =I4*2 -> 2 | J5: =J4*2 -> 2 | K5: =K4*2 -> 0.014 | L5: 2 | M5: =I5*$C$24*L5 -> 12 | N5: =M5*$C$26 -> 6 | O5: =($C$25/$C$24)*(M5-N5) -> 120 | P5: =($C$22+K5*$C$25)/($C$25/$C$24)+J5*$C$24 -> 11.042
B6: 3 | C6: =SUM($C$4:C5) -> 15 | D6: =SUM($C$4:C6) -> 30 | E6: =D6/$C$19 -> 0.25 | F6: =E6/$C$20 -> 0.5 | H6: Пара | I6: =I5*2 -> 4 | J6: =J5*2 -> 4 | K6: =K5*2 -> 0.028 | L6: 3 | M6: =I6*$C$24*L6 -> 36 | N6: =M6*$C$26 -> 18 | O6: =($C$25/$C$24)*(M6-N6) -> 360 | P6: =($C$22+K6*$C$25)/($C$25/$C$24)+J6*$C$24 -> 17.084
B7: 4 | C7: =SUM($C$4:C6) -> 30 | D7: =SUM($C$4:C7) -> 60 | E7: =D7/$C$19 -> 0.5 | F7: =E7/$C$20 -> 1 | H7: Нефти | I7: =I6*2 -> 8 | J7: =J6*2 -> 8 | K7: =K6*2 -> 0.056 | L7: 4 | M7: =I7*$C$24*L7 -> 96 | N7: =M7*$C$26 -> 48 | O7: =($C$25/$C$24)*(M7-N7) -> 960 | P7: =($C$22+K7*$C$25)/($C$25/$C$24)+J7*$C$24 -> 29.168
B8: 5 | C8: =SUM($C$4:C7) -> 60 | D8: =SUM($C$4:C8) -> 120 | E8: =D8/$C$19 -> 1 | F8: =E8/$C$20 -> 2 | H8: Атома | I8: =I7*2 -> 16 | J8: =J7*2 -> 16 | K8: =K7*2 -> 0.112 | L8: 5 | M8: =I8*$C$24*L8 -> 240 | N8: =M8*$C$26 -> 120 | O8: =($C$25/$C$24)*(M8-N8) -> 2400 | P8: =($C$22+K8*$C$25)/($C$25/$C$24)+J8*$C$24 -> 53.336
B9: 6 | C9: =SUM($C$4:C8) -> 120 | D9: =SUM($C$4:C9) -> 240 | E9: =D9/$C$19 -> 2 | F9: =E9/$C$20 -> 4 | H9: Новейшая | I9: =I8*2 -> 32 | J9: =J8*2 -> 32 | K9: =K8*2 -> 0.224 | L9: 6 | M9: =I9*$C$24*L9 -> 576 | N9: =M9*$C$26 -> 288 | O9: =($C$25/$C$24)*(M9-N9) -> 5760 | P9: =($C$22+K9*$C$25)/($C$25/$C$24)+J9*$C$24 -> 101.672
B10: 7 | C10: =SUM($C$4:C9) -> 240 | D10: =SUM($C$4:C10) -> 480 | E10: =D10/$C$19 -> 4 | F10: =E10/$C$20 -> 8
B11: 8 | C11: =SUM($C$4:C10) -> 480 | D11: =SUM($C$4:C11) -> 960 | E11: =D11/$C$19 -> 8 | F11: =E11/$C$20 -> 16
B12: 9 | C12: =SUM($C$4:C11) -> 960 | D12: =SUM($C$4:C12) -> 1920 | E12: =D12/$C$19 -> 16 | F12: =E12/$C$20 -> 32
B13: 10 | C13: =SUM($C$4:C12) -> 1920 | D13: =SUM($C$4:C13) -> 3840 | E13: =D13/$C$19 -> 32 | F13: =E13/$C$20 -> 64
B17: Константа | C17: Значение | E17: Соотношение игрового времени к реальному
B18: Время базового обучения, мин | C18: 5 | E18: Реальное | F18: Игровое
B19: Сессия , мин | C19: 120 | E19: 4 часа | F19: сутки
B20: Сессий в день | C20: 0.5 | E20: 1 час | F20: 6 часов
B21: Базовый ДПС, хит | C21: 1 | E21: 1 минута | F21: 6 минут
B22: Базовые хиты персонажа, хит | C22: 100
B23: Базовая броня, хит | C23: 1
B24: Базовая атака, сек | C24: 3
B25: Убийство равноценного противника, сек | C25: 60
B26: Ожидаемое отражение вреда броней монстра | C26: 0.5
B27: Базовый коэффициент времени | C27: 6
B28: Базовый срок регенерации здоровья, игровые часы | C28: 24
B29: Базовый срок голода, игровые часы | C29: 96
B30: Базовый срок жажды, игровые часы | C30: 48
B31: Базовый срок восстановления ментального состояния, игровые часы | C31: 72
B32: Базовый срок восстановления состояния тела, игровые часы | C32: 2
B33: Базовый срок выведения токсинов, игровые часы | C33: 24
... B43: Базовая усталость при средней деятельности, игровой час | C43: 8
B44: Базовое время полной потери ментала, игровые часы | C44: =5*24 -> 120
B45: Минимальное время полной потери менталы, игровые часы | C45: 48

Sheet Параметры персонажа
A3: есть явная положительная маркировка на экране | C3: Основные параметры | D3: 100 пунктов [6] | E3: 99-80 пунктов [5] | F3: 79-60 пунктов [4] | G3: 59-40 пунктов [3] | H3: 39-20 пунктов [2] | I3: 19-1 пункт [1] | J3: 0 пунктов [0] | M3: Производные параметры | N3: Значение | O3: Тип | P3: Реген за тик
A4: есть слабая положительная маркировка на экране | C4: Здоровье | D4: Ускорение восстановления 2 | E4: Ускорение восстановления 1 | G4: Штраф на скорость движений 1 | H4: Штраф на скорость движений 2, ускорение истощения 1 | I4: Штраф на скорость движений 3, ускорение истощения 2, замедление восстановления 1 | J4: При смерти или без сознания, ускорение истощения 3, замедление восстановления 2 | M4: Скорость восстановления здоровья в игровой час | N4: =ROUNDUP(100/'Базовые таблицы'!C28,0) -> 5 | O4: Восстановление | P4: =N4/$N$32/2 -> 0.0041666667
A5: нет маркировки на экране | C5: Сытость | D5: Ускорение восстановления 5 | E5: Ускорение восстановления 2 | F5: Ускорение восстановления 1 | H5: замедление восстановления 1 | I5: замедление восстановления 3 | J5: замедление восстановления 10, повреждение здоровья 1 | M5: Скорость падения сытости в игровой час | N5: =ROUNDUP(100/'Базовые таблицы'!C29,0) -> 2 | O5: Истощение | P5: =N5/$N$32/2 -> 0.0016666667
A6: есть редкий периодический звуковой маркер | C6: Гидрация | D6: Ускорение восстановления 5 | E6: Ускорение восстановления 3 | F6: Ускорение восстановления 2 | H6: замедление восстановления 1 | I6: замедление восстановления 3, повреждение здоровья 1 | J6: замедление восстановления 10, повреждение здоровья 2 | M6: Скорость падения гидрации в игровой час | N6: =ROUNDUP(100/'Базовые таблицы'!C30,1) -> 2.1 | O6: Истощение | P6: =N6/$N$32/2 -> 0.00175
A7: есть слабая отрицательная маркировка на экране, периодический звуковой маркер | C7: Ментальное состояние | D7: Улучшенное восприятие 2, Ускорение восстановления 2 | E7: Улучшенное восприятие 1, Ускорение восстановления 1 | G7: Штраф на скорость действий 1 | H7: Ухудшение восприятия 1, Штраф на скорость действий 1 | I7: Ухудшение восприятия 2, Штраф на скорость действий 2 | J7: Ухудшение восприятия 3, Штраф на скорость действий 3 | M7: Скорость восстановления ментального состояния в игровой час | N7: =ROUNDUP(100/'Базовые таблицы'!C31,1) -> 1.4 | O7: Восстановление | P7: =N7/$N$32/2 -> 0.0011666667
A8: есть явная маркировка на экране, частый звуковой маркер | C8: Температурный баланс - перегрев | D8: замедление восстановления 3, повреждение здоровья 2, Штраф на скорость движений 1, повреждение гидрации 2 | E8: замедление восстановления 2, повреждение здоровья 1, повреждение гидрации 1 | F8: замедление восстановления 1 | J8: Ускорение восстановления 1 | M8: Скорость восстановления бодрости в игровой час | N8: =ROUNDUP(100/'Базовые таблицы'!C32,1) -> 50 | O8: Восстановление | P8: =N8/$N$32/2 -> 0.041666667
A9: сверх-явная маркировка на экране, навязчивый звуковой маркер | C9: Температурный баланс - переохлаждение | D9: замедление восстановления 3, повреждение здоровья 1, Штраф на скорость движений 1, повреждение сытости 2 | E9: замедление восстановления 2, повреждение сытости 1 | F9: замедление восстановления 1 | J9: Ускорение восстановления 1 | M9: Скорость выведения токсинов в игровой час | N9: =ROUNDUP(100/'Базовые таблицы'!C33,1) -> 4.2 | O9: Восстановление | P9: =N9/$N$32/2 -> 0.0035
C10: Бодрость | D10: Бонус скорости движений 2 | E10: Бонус скорости движений 1 | H10: Штраф на скорость движений 1 | I10: Штраф на скорость движений 2, ускорение истощения 1, Штраф на скорость действий 1 | J10: Штраф на скорость движений 3, запрет бега, прыжков, паркура и т.д., ускорение истощения 2, Штраф на скорость действий 2 | M10: Скорость выведения радиации в игровой час | N10: =ROUNDUP(100/'Базовые таблицы'!C34,1) -> 0.5 | O10: Восстановление | P10: =N10/$N$32/2 -> 0.00041666667
C11: Отравление | D11: замедление восстановления 5, повреждение здоровья 3, повреждение гидрации 5, повреждение сытости 2 | E11: замедление восстановления 4, повреждение здоровья 2, повреждение гидрации 3, повреждение сытости 1 | F11: замедление восстановления 3, повреждение здоровья 1, повреждение гидрации 2 | G11: замедление восстановления 2, повреждение гидрации 1 | H11: замедление восстановления 1 | P11: =N11/$N$32/2 -> 0
C12: Радиационное заражение | D12: замедление восстановления 5, повреждение здоровья 5, повреждение сытости 2, повреждение гидрации 2 | E12: замедление восстановления 4, повреждение здоровья 3, повреждение сытости 1, повреждение гидрации 1 | F12: замедление восстановления 3, повреждение здоровья 1 | G12: замедление восстановления 2 | H12: замедление восстановления 1 | M12: Скорость выведения болевого шока в игровой час | N12: =ROUNDUP(100/'Базовые таблицы'!C36,1) -> 16.7 | O12: Восстановление | P12: =N12/$N$32/2 -> 0.013916667
C13: Болевой шок | D13: замедление восстановления 5, повреждение здоровья 3, повреждение ментала 3 | E13: замедление восстановления 4, повреждение здоровья 2, повреждение ментала 2 | F13: замедление восстановления 3, повреждение ментала 1 | G13: замедление восстановления 2 | H13: замедление восстановления 1 | M13: Шаг ускорения восстановления | N13: =10% -> 0.1 | O13: Модификатор
M14: Шаг замедления восстановления | N14: -0.1 | O14: Модификатор
K15: =0.01*60*15 -> 9 | M15: Шаг ускорения истощения | N15: =10% -> 0.1 | O15: Модификатор
M16: Шаг замедления истощения | N16: -0.1 | O16: Модификатор
C17: Внешние факторы | M17: Лимит макс восстановления | N17: 5 | O17: Лимит
C18: Основные параметры | D18: Повышение разовое | E18: Уменьшение разовое | F18: Повышение по времени | G18: Понижение по времени | H18: Ускорение естественного уменьшения | I18: Ускорение естественного повышения | M18: Лимит мин восстановления | N18: 0.01 | O18: Лимит
C19: Здоровье | D19: Стимуляторы 5+ эпоха | E19: Удары мобов, объекты ландшафта (лавины, кустарники), ловушки (колья, стекло и т.д.), явления внутри погоды (молнии, торнадо, летающие объекты), падение. | G19: Стимуляторы и медикаменты, погода (бури, самумы и т.д.) | I19: Отдых с учетом комфорта | M19: Лимит макс истощения | N19: =200% -> 2 | O19: Лимит
C20: Сытость | D20: Еда | E20: Постэффект некоторых напитков, медикаментов и наркотиков, Промывающие препараты | G20: Алкоголь, наркотики | M20: Лимит мин истощения | N20: 0.1 | O20: Лимит
C21: Гидрация | D21: Напитки | E21: Постэффект некоторых напитков, медикаментов и наркотиков, Промывающие препараты | G21: Алкоголь, наркотики | M21: Шаг бонуса скорости движения | N21: =5% -> 0.05 | O21: Модификатор
C22: Ментальное состояние | D22: Атаки пси-монстров, аномалии, смерть союзника | E22: Постэффект некоторых напитков, медикаментов и наркотиков | F22: Алкоголь, наркотики | G22: Нахождение в жутких местах, рядом с аномалией | I22: Красивые места, отдых с комфортом | M22: Шаг штрафа скорости движения | N22: -0.05 | O22: Модификатор
C23: Температурный баланс - перегрев | D23: Атаки огнем и горящим оружием | E23: Атаки холодом | F23: Подсчет ниже | H23: Ветер | I23: Яркое солнце | M23: Лимит макс скорости движения | N23: =150% -> 1.5 | O23: Лимит
C24: Температурный баланс - переохлаждение | D24: Атаки холодом | E24: Атаки огнем и горящим оружием | H24: Яркое солнце | I24: Ветер | M24: Лимит мин скорости движения | N24: 0.5 | O24: Лимит
C25: Бодрость | D25: Энергетики различного происхождения, наркотики | E25: Постэффект некоторых напитков, медикаментов и наркотиков, любые движения и действия - удары, прыжки, акробатика, крафт, добыча и т.д. | I25: Отдых, комфорт | M25: Скорость замерзания в игровой час | N25: =ROUNDUP(100/'Базовые таблицы'!C38,1) -> 12.5 | O25: Истощение | P25: =N25/$N$32/2 -> 0.010416667
C26: Отравление | D26: Употребление содержащей вещества воды и еды | E26: Промывающие препараты | F26: Нахождение в отравленной местности, кислотные дожди | H26: Лекарства | M26: Скорость перегреа игровой час | N26: =ROUNDUP(100/'Базовые таблицы'!C37,1) -> 25 | O26: Истощение | P26: =N26/$N$32/2 -> 0.020833333
C27: Радиационное заражение | D27: Употребление содержащей вещества воды и еды | E27: Промывающие препараты, антирадиационные препараты | F27: Нахождение в радиационной местности, ношение радиоактивных предметов, попадание под радиоактивные осадки | H27: Лекарства | M27: Шаг скорости повреждения здоровья в игровой час | N27: =ROUNDUP(100/'Базовые таблицы'!C41,1) -> 2.1 | O27: Урон | P27: =N27/$N$32/2 -> 0.00175
C28: Болевой шок | D28: Получение урона или травмы | E28: Антишоковые препараты, алкоголь, наркотики | F28: Активность с травмой | H28: Обезбаливающие | M28: Лимит скорости повреждения здоровья в игровой час | N28: =ROUNDUP(100/'Базовые таблицы'!C42,1) -> 100 | O28: Лимит | P28: =N28/$N$32/2 -> 0.083333333
M29: Минимальная комфортная температура, С | N29: 10
M30: Максимальная комфортная температура, С | N30: 25
M31: Скорость таймера обновления состояния, в секундах. | N31: 0.5
C32: Параметры влияющие на терморегуляцию | M32: Скорость течения игрового часа, в секундах | N32: =60*60/'Базовые таблицы'!C27 -> 600
C33: Параметр | D33: Базовое значение | M33: Трата бодрости, единичное слабое действие (бросок легкого предмета, удар рукой или ножем) | N33: =ROUNDUP(N36/$N$32*'Базовые таблицы'!$C$24,2) -> 0.32 | O33: Истощение
C34: Температура окружающей среды | D34: от погоды | M34: Трата бодрости, единичное среднее действие (толчок противника, пинок, прыжок, удар копьем, выстрел мз лука, метание ножей и копий) | N34: =ROUNDUP(N37/$N$32*'Базовые таблицы'!$C$24,2) -> 0.63 | O34: Истощение
C35: Минимальная комфортная температура, С | D35: 10 | M35: Трата бодрости, единичное сильное действие (паркур, слом преград) | N35: =ROUNDUP(N38/$N$32*'Базовые таблицы'!$C$24,2) -> 0.94 | O35: Истощение
C36: Максимальная комфортная температура, С | D36: 25 | M36: Трата бодрости, длительное слабое действие (ходьба, крафт) игровой час | N36: =ROUNDUP(100/'Базовые таблицы'!C43,1)+N8 -> 62.5 | O36: Истощение | P36: =N36/$N$32/2 -> 0.052083333
C37: Термоизоляция одежды, % | D37: сумма по одежде | G37: Температура среды | H37: 10 | M37: Трата бодрости, длительное среднее действие (легкий бег, плавание) игровой час | N37: =N36*2 -> 125 | O37: Истощение | P37: =N37/$N$32/2 -> 0.10416667
C38: Тепловыведение одежды, % | D38: сумма по одежде | G38: Изменение температуры от окружения | H38: 2 | M38: Трата бодрости, длительное сильное действие (спринт, подъем по вертикальной лестнице, добыча ископаемых) игровой час | N38: =N36*3 -> 187.5 | O38: Истощение | P38: =N38/$N$32/2 -> 0.15625
C39: Изменение минимальной комфортной температуры одежды, С | D39: сумма по одежде | G39: Температура ощущений | H39: =H37+H38 -> 12 | M39: Коэффициент ускорения восстановления здоровья для отдыха | N39: 0.25 | O39: Модификатор
C40: Изменение максимальной комфортной температуры одежды, С | D40: сумма по одежде | G40: Фактор изоляции | H40: 3 | M40: Коэффициент ускорения восстановления бодрости для отдыха | N40: 2 | O40: Модификатор
C41: Термоизоляция помещения, % | D41: от укрытия | H41: 100 | M41: Коэффициент ускорения восстановления ментала для отдыха | N41: 0.1 | O41: Модификатор
C42: Температура объектов окружения | D42: среднее по объектам | M42: Коэффициент ускорения восстановления здоровья для сна | N42: 1 | O42: Модификатор
...

Sheet Навыки персонажа
B2: Ближний бой
B3: Уровень | C3: Урон | D3: Скорость
B4: 0 | C4: 0.05
B5: 1 | C5: 0.2
B6: 2 | C6: 0.4
B7: 3 | C7: 0.6
B8: 4 | C8: 0.8
B9: 5 | C9: 1
B10: 6 | C10: 1.25
B11: 7 | C11: 1.5
B12: 8 | C12: 1.75
B13: 9 | C13: 2
B14: 10 | C14: 2.5
B16: Живучесть
B17: Уровень | C17: Потеря бордрости от урона
B18: 0 | C18: 3
B19: 1 | C19: 2
B20: 2 | C20: 1.75
B21: 3 | C21: 1.5
B22: 4 | C22: 1.25
B23: 5 | C23: 1
B24: 6 | C24: 0.75
B25: 7 | C25: 0.5
B26: 8 | C26: 0.25
B27: 9 | C27: 0.1
B28: 10 | C28: 0.05

Sheet Оазисы и локации
B2: Город-лес
B3: Многоэтажка | C3: вес при генерации | D3: тут картинка | E3: тут ссылка на ассет

Sheet Существа и биомы
B2: Параметры мобов | C2: Изменерние | D2: Значение
B3: Здоровье
B4: Регенерация здоровья
B5: Бодрость
B6: Регенерация бодрости
B7: Храбрость
B8: Вес
B9: Период размножения
B10: Рождаемость

Sheet Температура и погода
B1: Таблица источников тепла
B2: Источник | C2: Радиус, метр | D2: Температура | E2: Мощность | H2: 1 | I2: Вычисление текущей базовой температы | J2: Смотрим таблицу сезонов, модифицируем на день/ночь | M2: Условия продолжения
B3: Человек | C3: 0.3 | D3: 36.6 | E3: 1 | H3: 2 | I3: Старт с базовой погоды для месяца | J3: Всегда запускается именно эта, если при переходе на продолжение не найдена другая погода | M3: Температура
H4: 3 | I4: Выбор периода действия погоды | J4: указано для каждой погоды - рандом мин-макс | M4: Сезон/месяц
H5: 4 | I5: Модификация списка продолжений | J5: Проверка условий доступных продолжений, исключение недоступных | M5: Время суток
H6: 5 | I6: Выбор следующий погоды | J6: рандом по весам из всего списка | M6: Игровое условие аномалии
H7: 6 | I7: Переход в п.3 | M7: Пункты опасности????
J8: Системе известны 3 последующие погоды
B14: Таблица видов (уровней) укрытий
B27: Таблица базовой температуры по месяцам
B28: Месяц | C28: умеренный | D28: субполярный | E28: субтропик
B29: январь | C29: -10
B30: февраль | C30: -15
B31: март | C31: -5
B32: апрель | C32: 5
B33: май | C33: 10
B34: июнь | C34: 15
B35: июль | C35: 25
B36: август | C36: 20
B37: сентябрь | C37: 15
B38: октябрь | C38: 5
B39: ноябрь | C39: 0
B40: декабрь | C40: -5
B43: Таблица светового дня по месяцам
B44: Месяц | C44: умеренный | D44: субполярный | E44: субтропик
B45: январь
B46: февраль
B47: март
B48: апрель
B49: май
B50: июнь
B51: июль
B52: август
B53: сентябрь
B54: октябрь
B55: ноябрь
B56: декабрь

Sheet Инвентарь
B2: Таблица снаряжения | AB2: ККал на 1 пункт еды | AC2: =(AC3*'Базовые таблицы'!C29/24)/100 -> 200
B3: Название | C3: Эпоха | D3: Вес | E3: слот | F3: Прочность | G3: Мин комф тем, С | H3: Макс комф тем, С | I3: Термоизоляция, % | J3: Тепловыведение, % | K3: Влагостойкость, % | L3: слот инвентаря | M3: уменьш. веса | N3: карманы | O3: Броня ближний бой | P3: Броня дальний бой | Q3: Прочность | R3: Шанс повреждения | S3: Допсвойство | AB3: ККал на сутки | AC3: 5000
AB4: Воды на сутки, л | AC4: 4
AB5: литров на 1 пункт гидрации | AC5: =(AC4*'Базовые таблицы'!C30/24)/100 -> 0.08
AB6: ячейка инвентаря , литров | AC6: 5
B15: Таблица расходников
B16: Название | C16: Эпоха | D16: Вес | E16: Размер | F16: Пак | G16: Применение | H16: Здоровье | I16: Сытость | J16: Гидрация | K16: Бодрость | L16: Болевой шок | M16: Отравление | N16: Ментал | O16: Консерва | P16: порча | Q16: Шанс порчи в сутки | R16: Допсвойство
B17: Мясо мелкой дичи сырое | C17: Примитивная | D17: 0.8 | E17: обычный | F17: 5 | G17: перорально | I17: 4 | J17: 0 | O17: нет | P17: да | Q17: 0.5
B18: Мясо мелкой дичи жареное | C18: Примитивная | D18: 0.7 | E18: обычный | F18: 5 | G18: перорально | I18: 6 | J18: -1 | O18: нет | P18: да | Q18: 0.25
B19: Мясо мелкой дичи сушеное | C19: Примитивная | D19: 0.5 | E19: обычный | F19: 10 | G19: перорально | I19: 5 | J19: -3 | O19: нет | P19: нет | Q19: 0
B20: Рыба малая сырая | C20: Примитивная | D20: 0.6 | E20: обычный | F20: 5 | G20: перорально | I20: 3 | J20: 0 | O20: нет | P20: да | Q20: 0.75
B21: Рыба малая жареная | C21: Примитивная | D21: 0.5 | E21: обычный | F21: 5 | G21: перорально | I21: 4 | J21: -1 | O21: нет | P21: да | Q21: 0.5
B22: Рыба малая сушеная | C22: Примитивная | D22: 0.3 | E22: обычный | F22: 10 | G22: перорально | I22: 3 | J22: -2 | O22: нет | P22: да | Q22: 0.1
B23: Дикая кустовая ягода (бузина, шиповник) | C23: Примитивная | D23: 0.05 | E23: обычный | F23: 100 | G23: перорально | I23: 1 | J23: 1 | O23: нет | P23: да | Q23: 0.2 | R23: Ядовитая в 10% (20-50 отравления)
B24: Гриб мелкий | C24: Примитивная | D24: 0.1 | E24: обычный | F24: 50 | G24: перорально | I24: 1 | J24: 0 | O24: нет | P24: да | Q24: 0.5 | R24: Ядовитый в 20% (30-75 отравления)
B25: Гриб мелкий жареный | C25: Примитивная | D25: 0.08 | E25: обычный | F25: 75 | G25: перорально | I25: 2 | J25: 0 | O25: нет | P25: да | Q25: 0.25 | R25: Ядовитый в 20% (5-10 отравления)
B26: Гриб мелкий сушеный | C26: Примитивная | D26: 0.05 | E26: обычный | F26: 100 | G26: перорально | I26: 2 | J26: 0 | O26: нет | P26: нет | Q26: 0 | R26: Ядовитый в 20% (10-15 отравления)
B27: Гриб средний | C27: Примитивная | D27: 0.2 | E27: обычный | F27: 25 | G27: перорально | I27: 2 | J27: 0 | O27: нет | P27: да | Q27: 0.5 | R27: Ядовитый в 20% (50-100 отравления)
B28: Гриб средний жареный | C28: Примитивная | D28: 0.1 | E28: обычный | F28: 50 | G28: перорально | I28: 5 | J28: -1 | O28: нет | P28: да | Q28: 0.25 | R28: Ядовитый в 20% (10-20 отравления)
B29: Гриб средний сушеный | C29: Примитивная | D29: 0.07 | E29: обычный | F29: 75 | G29: перорально | I29: 4 | J29: -2 | O29: нет | P29: нет | Q29: 0 | R29: Ядовитый в 20% (25-50 отравления)
B30: Корешок съедобный | C30: Примитивная | D30: 0.3 | E30: обычный | F30: 10 | G30: перорально | I30: 2 | J30: 0 | O30: нет | P30: нет | Q30: 0
B31: Орех лесной | C31: Примитивная | D31: 0.01 | E31: обычный | F31: 100 | G31: перорально | I31: 1 | J31: 0 | O31: нет | P31: нет | Q31: 0
B32: Яйцо мелкое сырое | C32: Примитивная | D32: 0.1 | E32: обычный | F32: 50 | G32: перорально | I32: 2 | J32: 0 | O32: нет | P32: да | Q32: 0.05
B33: Яйцо среднее сырое | C33: Примитивная | D33: 0.3 | E33: обычный | F33: 20 | G33: перорально | I33: 5 | J33: 1 | O33: нет | P33: да | Q33: 0.05
B34: Дикое яблоко | C34: Примитивная | D34: 0.2 | E34: обычный | F34: 25 | G34: перорально | I34: 2 | J34: 1 | O34: нет | P34: да | Q34: 0.05
B35: Дикое яблоко сушеное | C35: Примитивная | D35: 0.1 | E35: обычный | F35: 50 | G35: перорально | I35: 2 | J35: -1 | O35: нет | P35: нет | Q35: 0
B36: Дикая груша | C36: Примитивная | D36: 0.2 | E36: обычный | F36: 25 | G36: перорально | I36: 3 | J36: 0 | O36: нет | P36: да | Q36: 0.1
B37: Дикая груша сушеная | C37: Примитивная | D37: 0.1 | E37: обычный | F37: 50 | G37: перорально | I37: 3 | J37: -1 | O37: нет | P37: нет | Q37: 0
B38: Дикий виноград | C38: Примитивная | D38: 0.1 | E38: обычный | F38: 50 | G38: перорально | I38: 1 | J38: 1 | O38: нет | P38: да | Q38: 0.15
B39: Изюм | C39: Примитивная | D39: 0.05 | E39: обычный | F39: 100 | G39: перорально | I39: 1 | J39: 0 | O39: нет | P39: да | Q39: 0.05
B40: Желуди | C40: Примитивная | D40: 0.15 | E40: обычный | F40: 30 | G40: перорально | I40: 1 | J40: -1 | O40: нет | P40: нет | Q40: 0
B41: Желуди жареные | C41: Примитивная | D41: 0.15 | E41: обычный | F41: 30 | G41: перорально | I41: 2 | J41: -1 | O41: нет | P41: нет | Q41: 0
B42: Каштаны | C42: Примитивная | D42: 0.15 | E42: обычный | F42: 30 | G42: перорально | I42: 3 | J42: -1 | O42: нет | P42: нет | Q42: 0 | R42: Ядовитый в 20% (25-50 отравления)
B43: Каштаны жареные | C43: Примитивная | D43: 0.1 | E43: обычный | F43: 50 | G43: перорально | I43: 4 | J43: -1 | O43: нет | P43: да | Q43: 0.05
B44: Дикая слива | C44: Примитивная | E44: обычный | F44: 0.1 | G44: перорально | I44: 1 | J44: 1 | O44: нет | P44: да | Q44: 0.15
B45: Дикая слива сушеная | C45: Примитивная | E45: обычный | F45: 0.05 | G45: перорально | I45: 1 | J45: 0 | O45: нет | P45: да | Q45: 0.01
B46: Пресная чистая вода | C46: Примитивная | D46: 0.5 | E46: обычный | F46: 10 | G46: перорально | I46: 0 | J46: 6 | O46: да | P46: да | Q46: 0.05
B47: Ключевая вода | C47: Примитивная | D47: 0.5 | E47: обычный | F47: 10 | G47: перорально | I47: 0 | J47: 7 | O47: да | P47: да | Q47: 0.1 | R47: ядовитая в 1% (1-5 отравления)
B48: Речная вода | C48: Примитивная | D48: 0.5 | E48: обычный | F48: 10 | G48: перорально | I48: 0 | J48: 5 | O48: нет | P48: да | Q48: 0.15 | R48: ядовитая в 5% (1-5 отравления)
B49: Вода дождевая чистая | C49: Примитивная | D49: 0.5 | E49: обычный | F49: 10 | G49: перорально | I49: 0 | J49: 5 | O49: нет | P49: да | Q49: 0.15 | R49: ядовитая в 1% (1-5 отравления) | S49: радиоативная в 5% (1-5 радиации)
...

Sheet Бой
B2: Константа | C2: Значение | H2: Алгоритм расчета урона и последствий (после попадания) в ближнем бою
B3: Шанс крит урона | C3: 0.01 | H3: Получение чистого урона от оружия (например дубина) | I3: ='Инвентарь'!I77 -> 2
B4: Увеличение урона при крите | C4: 2 | H4: Корректируем урон по прочности оружия (например он 4/5) | I4: =I3*4/'Инвентарь'!T77 -> 1.6
B5: Минимальный наносимый урон | C5: ='Параметры персонажа'!P4*2*60 -> 0.5 | H5: Корректируем по навыку персонажа (например 6) | I5: =I4*'Навыки персонажа'!C10 -> 2
H6: Персонаж цель теряет борость, равную урону с мод. за живучесть (например 3) | I6: =I5*'Навыки персонажа'!C21 -> 3
H7: Проверяем шанс критического урона (например он базовый) | I7: =C3 -> 0.01
H8: Умножаем на мод.крит урона если он был (например не было) | I8: =I5 -> 2
H9: Если был крит удар то игнорируем броню цели (например не было)
H10: Получаем чистую броню цели (например это шкурный доспех примитивной эпохи, броня 4) | I10: 4
H11: Корректируем броню по прочности (например доспех сильно изношен 2/10) | I11: =I10*2/10 -> 0.8
H12: Вычитаем из урона броню цели | I12: =I8-I11 -> 1.2
H13: Если броня не пробита, то цель получает минимальный наносимый урон и алгоритм прерывается | I13: =C5 -> 0.5
H14: Если урона было больше чем брони, то проверяется шанс порчи брони (например он 20%) | I14: 0.2
H15: Если он сработал, то броня теряет 1 прочности
H16: Проверяется шанс порчи оружия (по дубине) | I16: 0.2
H17: Если он сработал, то оружие теряет 1 прочности
H18: Округляем урон вверх | I18: =ROUNDUP(I12,0) -> 2
H19: Персонаж цель получает урон по здоровью | I19: =I18 -> 2
H20: Получаем модификатор к шоку от оружия | I20: ='Инвентарь'!L77 -> 1.5
H21: Персонаж цель получает шок с модификатором оружия и округлением вверх | I21: =Roundup(I19*I20,0) -> 3
H22: Проверяется шанс получения сильной раны | I22: =I19*'Параметры персонажа'!N67 -> 0.01
H23: Проверяется шанс получения средней раны (если не получена сильная) | I23: =I19*'Параметры персонажа'!N66 -> 0.04
H24: Проверяется шанс получения слабой раны (если не получена сильная или средняя) | I24: =I19*'Параметры персонажа'!N65 -> 0.1
H25: Например сработал шанс слабой раны - ее уровень 1 | I25: 1
H26: Получаем модификатор к кровотечению от оружия | I26: ='Инвентарь'!K77 -> 0.25
H27: Проверяется шанс получения сильного кровотечения | I27: =I25*'Параметры персонажа'!N70*I26 -> 0.025
H28: Проверяется шанс получения среднего кровотечения (если не получено сильное) | I28: =I25*'Параметры персонажа'!N69*I26 -> 0.0625
H29: Проверяется шанс получения слабого кровотечения (если не получено сильное или среднее) | I29: =I25*'Параметры персонажа'!N68*I26 -> 0.125
H30: Проверяется шанс получения перелома | I30: =I25*'Параметры персонажа'!N71 -> 0.05

Sheet DT_CharacterStatsConstants
A1: --- | B1: StatComment | C1: StatValue
A2: TemperatureOverheat | B2: Overhaet begins here, C | C2: 25.000000
A3: TemperatureFreezing | B3: Freezing begins here, C | C3: 10.000000
A4: StaminaRestoreSpeed | B4: Скорость восстановления выносливости в игровой час | C4: 1000.000000
A5: HealthRestoreSpeed | B5: Скорость восстановления здоровья в игровой час | C5: 9.000000
A6: HungerDecaySpeed | B6: Скорость падения сытости в игровой час | C6: -2.000000
A7: ThirstDecaySpeed | B7: Скорость падения гидрации в игровой час | C7: -2.100000
A8: SanityRestoreSpeed | B8: Скорость восстановления ментального состояния в игровой час | C8: 1.400000
A9: VigorRestoreSpeed | B9: Скорость восстановления бодрости в игровой час | C9: 50.000000
A10: ToxinsDecaySpeed | B10: Скорость выведения токсинов в игровой час | C10: -4.200000
A11: RadiationDecaySpeed | B11: Скорость выведения радиации в игровой час | C11: -0.500000
A12: PainshockDecaySpeed | B12: Скорость выведения болевого шока в игровой час | C12: -16.700000
... A39: SanityDecayStep | B39: Шаг истощения менталки, % | C39: -0.100000

Sheet DT_WorldConstants
A1: --- | B1: ConstantComment | C1: Value
A2: TimeSecondsPerGameHour | B2: Скорость течения игрового часа, за сколько секунд проходит игровой час | C2: 600
A3: SurvTimerUpdSpeed | B3: Скорость таймера обновления состояния, в секундах. | C3: 0.5
